<sdf version='1.7'>
  <model name='uma3_.SLDASM2'>
    <link name='base_link'>
      <inertial>
        <pose>-0.000689 -0.002137 0.004638 0 -0 0</pose>
        <mass>2.10772</mass>
        <inertia>
          <ixx>0.00603833</ixx>
          <ixy>1.12388e-05</ixy>
          <ixz>2.13754e-07</ixz>
          <iyy>0.00676009</iyy>
          <iyz>-1.75698e-06</iyz>
          <izz>0.00908173</izz>
        </inertia>
      </inertial>
      <collision name='base_link_collision'>
        <pose>0 0 0 0 -0 0</pose>
        <geometry>
          <mesh>
            <scale>1 1 1</scale>
            <uri>model://uam_control_interface/urdf/mesh/base_link.STL</uri>
          </mesh>
        </geometry>
      </collision>
      <visual name='base_link_visual'>
        <pose>0 0 0 0 -0 0</pose>
        <geometry>
          <mesh>
            <scale>1 1 1</scale>
            <uri>model://uam_control_interface/urdf/mesh/base_link.STL</uri>
          </mesh>
        </geometry>
      </visual>
    </link>
    <joint name='operator_1_joint' type='revolute'>
      <pose relative_to='base_link'>0.000871 0.000172 0.028455 0 -0 0</pose>
      <parent>base_link</parent>
      <child>operator_Link</child>
      <axis>
        <xyz>-0.01699 -0.999856 0</xyz>
        <limit>
          <lower>0</lower>
          <upper>0</upper>
          <effort>0</effort>
          <velocity>0</velocity>
        </limit>
        <dynamics>
          <spring_reference>0</spring_reference>
          <spring_stiffness>0</spring_stiffness>
        </dynamics>
      </axis>
    </joint>
    <link name='operator_Link'>
      <pose relative_to='operator_1_joint'>0 0 0 0 -0 0</pose>
      <inertial>
        <pose>-0.080013 0.002996 0.083256 0 -0 0</pose>
        <mass>2.81664</mass>
        <inertia>
          <ixx>0.0498843</ixx>
          <ixy>0.000155474</ixy>
          <ixz>0.00980071</ixz>
          <iyy>0.060379</iyy>
          <iyz>1.19798e-05</iyz>
          <izz>0.0122456</izz>
        </inertia>
      </inertial>
      <collision name='operator_Link_collision'>
        <pose>0 0 0 0 -0 0</pose>
        <geometry>
          <mesh>
            <scale>1 1 1</scale>
            <uri>model://uam_control_interface/urdf/mesh/operator_Link.STL</uri>
          </mesh>
        </geometry>
      </collision>
      <collision name='operator_Link_fixed_joint_lump__camera_Link_collision_1'>
        <pose>-0.1084 0.001842 0.21154 0 -0.5236 -0.016991</pose>
        <geometry>
          <mesh>
            <scale>1 1 1</scale>
            <uri>model://uam_control_interface/urdf/mesh/camera_Link.STL</uri>
          </mesh>
        </geometry>
      </collision>
      <collision name='operator_Link_fixed_joint_lump__end_Link_collision_2'>
        <pose>0.832191 -0.014141 0.480535 0 1.0472 -0.016991</pose>
        <geometry>
          <mesh>
            <scale>1 1 1</scale>
            <uri>model://uam_control_interface/urdf/mesh/end_Link.STL</uri>
          </mesh>
        </geometry>
      </collision>
      <collision name='operator_Link_fixed_joint_lump__end_effector_base_Link_collision_3'>
        <pose>0.257683 -0.004379 0.148795 2.0944 -0 -1.58779</pose>
        <geometry>
          <mesh>
            <scale>1 1 1</scale>
            <uri>model://uam_control_interface/urdf/mesh/end_effector_base_link.STL</uri>
          </mesh>
        </geometry>
      </collision>
      <visual name='operator_Link_visual'>
        <pose>0 0 0 0 -0 0</pose>
        <geometry>
          <mesh>
            <scale>1 1 1</scale>
            <uri>model://uam_control_interface/urdf/mesh/operator_Link.STL</uri>
          </mesh>
        </geometry>
      </visual>
      <visual name='operator_Link_fixed_joint_lump__camera_Link_visual_1'>
        <pose>-0.1084 0.001842 0.21154 0 -0.5236 -0.016991</pose>
        <geometry>
          <mesh>
            <scale>1 1 1</scale>
            <uri>model://uam_control_interface/urdf/mesh/camera_Link.STL</uri>
          </mesh>
        </geometry>
      </visual>
      <visual name='operator_Link_fixed_joint_lump__end_Link_visual_2'>
        <pose>0.832191 -0.014141 0.480535 0 1.0472 -0.016991</pose>
        <geometry>
          <mesh>
            <scale>1 1 1</scale>
            <uri>model://uam_control_interface/urdf/mesh/end_Link.STL</uri>
          </mesh>
        </geometry>
      </visual>
      <visual name='operator_Link_fixed_joint_lump__end_effector_base_Link_visual_3'>
        <pose>0.257683 -0.004379 0.148795 2.0944 -0 -1.58779</pose>
        <geometry>
          <mesh>
            <scale>1 1 1</scale>
            <uri>model://uam_control_interface/urdf/mesh/end_effector_base_link.STL</uri>
          </mesh>
        </geometry>
      </visual>
    </link>
    <joint name='end_effector::connect_joint' type='prismatic'>
      <pose relative_to='operator_Link'>0.515159 -0.008754 0.29747 2.0944 -0 -1.58779</pose>
      <parent>operator_Link</parent>
      <child>connect_Link</child>
      <axis>
        <xyz>0 0 1</xyz>
        <limit>
          <lower>0</lower>
          <upper>0</upper>
          <effort>0</effort>
          <velocity>0</velocity>
        </limit>
        <dynamics>
          <spring_reference>0</spring_reference>
          <spring_stiffness>0</spring_stiffness>
        </dynamics>
      </axis>
    </joint>
    <link name='connect_Link'>
      <pose relative_to='end_effector::connect_joint'>0 0 0 0 -0 0</pose>
      <inertial>
        <pose>0.00023 -0.008308 -0.339949 0 -0 0</pose>
        <mass>0.224535</mass>
        <inertia>
          <ixx>0.00261433</ixx>
          <ixy>-4.53611e-07</ixy>
          <ixz>-9.17011e-06</ixz>
          <iyy>0.00255743</iyy>
          <iyz>-9.3336e-05</iyz>
          <izz>0.000227535</izz>
        </inertia>
      </inertial>
      <collision name='connect_Link_collision'>
        <pose>0 0 0 0 -0 0</pose>
        <geometry>
          <mesh>
            <scale>1 1 1</scale>
            <uri>model://uam_control_interface/urdf/mesh/connect_Link.STL</uri>
          </mesh>
        </geometry>
      </collision>
      <collision name='connect_Link_fixed_joint_lump__move_base_Link_collision_1'>
        <pose>0 0 -0.4115 0 -0 0</pose>
        <geometry>
          <mesh>
            <scale>1 1 1</scale>
            <uri>model://uam_control_interface/urdf/mesh/move_base_Link.STL</uri>
          </mesh>
        </geometry>
      </collision>
      <visual name='connect_Link_visual'>
        <pose>0 0 0 0 -0 0</pose>
        <geometry>
          <mesh>
            <scale>1 1 1</scale>
            <uri>model://uam_control_interface/urdf/mesh/connect_Link.STL</uri>
          </mesh>
        </geometry>
      </visual>
      <visual name='connect_Link_fixed_joint_lump__move_base_Link_visual_1'>
        <pose>0 0 -0.4115 0 -0 0</pose>
        <geometry>
          <mesh>
            <scale>1 1 1</scale>
            <uri>model://uam_control_interface/urdf/mesh/move_base_Link.STL</uri>
          </mesh>
        </geometry>
      </visual>
    </link>
    <joint name='end_effector::wheel1_joint' type='revolute'>
      <pose relative_to='connect_Link'>0 0.085482 -0.4 0 -0 0</pose>
      <parent>connect_Link</parent>
      <child>wheel1_Link</child>
      <axis>
        <xyz>0 1 0</xyz>
        <limit>
          <lower>-1e+16</lower>
          <upper>1e+16</upper>
        </limit>
        <dynamics>
          <spring_reference>0</spring_reference>
          <spring_stiffness>0</spring_stiffness>
        </dynamics>
      </axis>
    </joint>
    <link name='wheel1_Link'>
      <pose relative_to='end_effector::wheel1_joint'>0 0 0 0 -0 0</pose>
      <inertial>
        <pose>-1e-06 -0.002478 -4.3e-05 0 -0 0</pose>
        <mass>0.041284</mass>
        <inertia>
          <ixx>2.4836e-06</ixx>
          <ixy>1.6072e-10</ixy>
          <ixz>-1.849e-10</ixz>
          <iyy>4.093e-06</iyy>
          <iyz>-1.5731e-10</iyz>
          <izz>2.4836e-06</izz>
        </inertia>
      </inertial>
      <collision name='wheel1_Link_collision'>
        <pose>0 0 0 0 -0 0</pose>
        <geometry>
          <mesh>
            <scale>1 1 1</scale>
            <uri>model://uam_control_interface/urdf/mesh/wheel1_Link.STL</uri>
          </mesh>
        </geometry>
      </collision>
      <visual name='wheel1_Link_visual'>
        <pose>0 0 0 0 -0 0</pose>
        <geometry>
          <mesh>
            <scale>1 1 1</scale>
            <uri>model://uam_control_interface/urdf/mesh/wheel1_Link.STL</uri>
          </mesh>
        </geometry>
      </visual>
    </link>
    <joint name='end_effector::wheel2_joint' type='revolute'>
      <pose relative_to='connect_Link'>0.07403 -0.042741 -0.4 0 0 -2.0944</pose>
      <parent>connect_Link</parent>
      <child>wheel2_Link</child>
      <axis>
        <xyz>0 1 0</xyz>
        <limit>
          <lower>-1e+16</lower>
          <upper>1e+16</upper>
        </limit>
        <dynamics>
          <spring_reference>0</spring_reference>
          <spring_stiffness>0</spring_stiffness>
        </dynamics>
      </axis>
    </joint>
    <link name='wheel2_Link'>
      <pose relative_to='end_effector::wheel2_joint'>0 0 0 0 -0 0</pose>
      <inertial>
        <pose>-1e-06 -0.002344 2e-06 0 -0 0</pose>
        <mass>0.040979</mass>
        <inertia>
          <ixx>2.4817e-06</ixx>
          <ixy>1.6072e-10</ixy>
          <ixz>-1.8492e-10</ixz>
          <iyy>4.0926e-06</iyy>
          <iyz>-1.5732e-10</iyz>
          <izz>2.4817e-06</izz>
        </inertia>
      </inertial>
      <collision name='wheel2_Link_collision'>
        <pose>0 0 0 0 -0 0</pose>
        <geometry>
          <mesh>
            <scale>1 1 1</scale>
            <uri>model://uam_control_interface/urdf/mesh/wheel2_Link.STL</uri>
          </mesh>
        </geometry>
      </collision>
      <visual name='wheel2_Link_visual'>
        <pose>0 0 0 0 -0 0</pose>
        <geometry>
          <mesh>
            <scale>1 1 1</scale>
            <uri>model://uam_control_interface/urdf/mesh/wheel2_Link.STL</uri>
          </mesh>
        </geometry>
      </visual>
    </link>
    <joint name='end_effector::wheel3_joint' type='revolute'>
      <pose relative_to='connect_Link'>-0.07403 -0.042741 -0.4 0 -0 2.0944</pose>
      <parent>connect_Link</parent>
      <child>wheel3_Link</child>
      <axis>
        <xyz>0 1 0</xyz>
        <limit>
          <lower>-1e+16</lower>
          <upper>1e+16</upper>
        </limit>
        <dynamics>
          <spring_reference>0</spring_reference>
          <spring_stiffness>0</spring_stiffness>
        </dynamics>
      </axis>
    </joint>
    <link name='wheel3_Link'>
      <pose relative_to='end_effector::wheel3_joint'>0 0 0 0 -0 0</pose>
      <inertial>
        <pose>-1e-06 -0.002344 2e-06 0 -0 0</pose>
        <mass>0.040979</mass>
        <inertia>
          <ixx>2.4817e-06</ixx>
          <ixy>1.6071e-10</ixy>
          <ixz>-1.8491e-10</ixz>
          <iyy>4.0926e-06</iyy>
          <iyz>-1.5732e-10</iyz>
          <izz>2.4817e-06</izz>
        </inertia>
      </inertial>
      <collision name='wheel3_Link_collision'>
        <pose>0 0 0 0 -0 0</pose>
        <geometry>
          <mesh>
            <scale>1 1 1</scale>
            <uri>model://uam_control_interface/urdf/mesh/wheel3_Link.STL</uri>
          </mesh>
        </geometry>
      </collision>
      <visual name='wheel3_Link_visual'>
        <pose>0 0 0 0 -0 0</pose>
        <geometry>
          <mesh>
            <scale>1 1 1</scale>
            <uri>model://uam_control_interface/urdf/mesh/wheel3_Link.STL</uri>
          </mesh>
        </geometry>
      </visual>
    </link>
    <joint name='rotor_0_joint' type='revolute'>
      <pose relative_to='base_link'>0.44207 0.2778 0.033856 0 -0 0</pose>
      <parent>base_link</parent>
      <child>rotor1_Link</child>
      <axis>
        <xyz>-0.25 0.43301 0.86603</xyz>
        <limit>
          <lower>0</lower>
          <upper>0</upper>
          <effort>0</effort>
          <velocity>0</velocity>
        </limit>
        <dynamics>
          <spring_reference>0</spring_reference>
          <spring_stiffness>0</spring_stiffness>
        </dynamics>
      </axis>
    </joint>
    <link name='rotor1_Link'>
      <pose relative_to='rotor_0_joint'>0 0 0 0 -0 0</pose>
      <inertial>
        <pose>0.001269 0.000215 -0.000505 0 -0 0</pose>
        <mass>0.0159144</mass>
        <inertia>
          <ixx>0.000193745</ixx>
          <ixy>5.85651e-05</ixy>
          <ixz>-3.66233e-05</ixz>
          <iyy>7.94267e-05</iyy>
          <iyz>8.67841e-05</iyz>
          <izz>0.000165216</izz>
        </inertia>
      </inertial>
      <collision name='rotor1_Link_collision'>
        <pose>0 0 0 0 -0 0</pose>
        <geometry>
          <mesh>
            <scale>1 1 1</scale>
            <uri>model://uam_control_interface/urdf/mesh/rotor1_Link.STL</uri>
          </mesh>
        </geometry>
      </collision>
      <visual name='rotor1_Link_visual'>
        <pose>0 0 0 0 -0 0</pose>
        <geometry>
          <mesh>
            <scale>1 1 1</scale>
            <uri>model://uam_control_interface/urdf/mesh/rotor1_Link.STL</uri>
          </mesh>
        </geometry>
      </visual>
    </link>
    <joint name='rotor_1_joint' type='revolute'>
      <pose relative_to='base_link'>0.019547 0.52175 0.033856 0 -0 0</pose>
      <parent>base_link</parent>
      <child>rotor2_Link</child>
      <axis>
        <xyz>0.5 0 0.86603</xyz>
        <limit>
          <lower>0</lower>
          <upper>0</upper>
          <effort>0</effort>
          <velocity>0</velocity>
        </limit>
        <dynamics>
          <spring_reference>0</spring_reference>
          <spring_stiffness>0</spring_stiffness>
        </dynamics>
      </axis>
    </joint>
    <link name='rotor2_Link'>
      <pose relative_to='rotor_1_joint'>0 0 0 0 -0 0</pose>
      <inertial>
        <pose>0.000229 0.001028 -0.000896 0 -0 0</pose>
        <mass>0.0159143</mass>
        <inertia>
          <ixx>0.000101187</ixx>
          <ixy>8.46794e-05</ixy>
          <ixz>6.81234e-05</ixz>
          <iyy>0.00015735</iyy>
          <iyz>-4.88878e-05</iyz>
          <izz>0.000179847</izz>
        </inertia>
      </inertial>
      <collision name='rotor2_Link_collision'>
        <pose>0 0 0 0 -0 0</pose>
        <geometry>
          <mesh>
            <scale>1 1 1</scale>
            <uri>model://uam_control_interface/urdf/mesh/rotor2_Link.STL</uri>
          </mesh>
        </geometry>
      </collision>
      <visual name='rotor2_Link_visual'>
        <pose>0 0 0 0 -0 0</pose>
        <geometry>
          <mesh>
            <scale>1 1 1</scale>
            <uri>model://uam_control_interface/urdf/mesh/rotor2_Link.STL</uri>
          </mesh>
        </geometry>
      </visual>
    </link>
    <joint name='rotor_2_joint' type='revolute'>
      <pose relative_to='base_link'>-0.46162 0.24395 0.033856 0 -0 0</pose>
      <parent>base_link</parent>
      <child>rotor3_Link</child>
      <axis>
        <xyz>-0.25 -0.43301 0.86603</xyz>
        <limit>
          <lower>0</lower>
          <upper>0</upper>
          <effort>0</effort>
          <velocity>0</velocity>
        </limit>
        <dynamics>
          <spring_reference>0</spring_reference>
          <spring_stiffness>0</spring_stiffness>
        </dynamics>
      </axis>
    </joint>
    <link name='rotor3_Link'>
      <pose relative_to='rotor_2_joint'>0 0 0 0 -0 0</pose>
      <inertial>
        <pose>0.000358 0.001336 7e-06 0 -0 0</pose>
        <mass>0.0159143</mass>
        <inertia>
          <ixx>1.96957e-05</ixx>
          <ixy>5.28965e-05</ixy>
          <ixz>-3.11372e-05</ixz>
          <iyy>0.000204524</iyy>
          <iyz>7.94496e-06</iyz>
          <izz>0.000214163</izz>
        </inertia>
      </inertial>
      <collision name='rotor3_Link_collision'>
        <pose>0 0 0 0 -0 0</pose>
        <geometry>
          <mesh>
            <scale>1 1 1</scale>
            <uri>model://uam_control_interface/urdf/mesh/rotor3_Link.STL</uri>
          </mesh>
        </geometry>
      </collision>
      <visual name='rotor3_Link_visual'>
        <pose>0 0 0 0 -0 0</pose>
        <geometry>
          <mesh>
            <scale>1 1 1</scale>
            <uri>model://uam_control_interface/urdf/mesh/rotor3_Link.STL</uri>
          </mesh>
        </geometry>
      </visual>
    </link>
    <joint name='rotor_3_joint' type='revolute'>
      <pose relative_to='base_link'>-0.46162 -0.24395 0.033856 0 -0 0</pose>
      <parent>base_link</parent>
      <child>rotor4_Link</child>
      <axis>
        <xyz>-0.25 0.43301 0.86603</xyz>
        <limit>
          <lower>0</lower>
          <upper>0</upper>
          <effort>0</effort>
          <velocity>0</velocity>
        </limit>
        <dynamics>
          <spring_reference>0</spring_reference>
          <spring_stiffness>0</spring_stiffness>
        </dynamics>
      </axis>
    </joint>
    <link name='rotor4_Link'>
      <pose relative_to='rotor_3_joint'>0 0 0 0 -0 0</pose>
      <inertial>
        <pose>-0.0007 -0.001122 -0.000405 0 -0 0</pose>
        <mass>0.0159143</mass>
        <inertia>
          <ixx>0.000124379</ixx>
          <ixy>8.30036e-05</ixy>
          <ixz>-6.88692e-05</ixz>
          <iyy>0.000145184</iyy>
          <iyz>6.09561e-05</iyz>
          <izz>0.000168819</izz>
        </inertia>
      </inertial>
      <collision name='rotor4_Link_collision'>
        <pose>0 0 0 0 -0 0</pose>
        <geometry>
          <mesh>
            <scale>1 1 1</scale>
            <uri>model://uam_control_interface/urdf/mesh/rotor4_Link.STL</uri>
          </mesh>
        </geometry>
      </collision>
      <visual name='rotor4_Link_visual'>
        <pose>0 0 0 0 -0 0</pose>
        <geometry>
          <mesh>
            <scale>1 1 1</scale>
            <uri>model://uam_control_interface/urdf/mesh/rotor4_Link.STL</uri>
          </mesh>
        </geometry>
      </visual>
    </link>
    <joint name='rotor_4_joint' type='revolute'>
      <pose relative_to='base_link'>0.019547 -0.52175 0.033856 0 -0 0</pose>
      <parent>base_link</parent>
      <child>rotor5_Link</child>
      <axis>
        <xyz>0.5 0 0.86603</xyz>
        <limit>
          <lower>0</lower>
          <upper>0</upper>
          <effort>0</effort>
          <velocity>0</velocity>
        </limit>
        <dynamics>
          <spring_reference>0</spring_reference>
          <spring_stiffness>0</spring_stiffness>
        </dynamics>
      </axis>
    </joint>
    <link name='rotor5_Link'>
      <pose relative_to='rotor_4_joint'>0 0 0 0 -0 0</pose>
      <inertial>
        <pose>0.000182 -0.00106 -0.00087 0 -0 0</pose>
        <mass>0.0159144</mass>
        <inertia>
          <ixx>9.47637e-05</ixx>
          <ixy>-8.06363e-05</ixy>
          <ixz>7.18324e-05</ixz>
          <iyy>0.000165916</iyy>
          <iyz>4.65537e-05</iyz>
          <izz>0.000177706</izz>
        </inertia>
      </inertial>
      <collision name='rotor5_Link_collision'>
        <pose>0 0 0 0 -0 0</pose>
        <geometry>
          <mesh>
            <scale>1 1 1</scale>
            <uri>model://uam_control_interface/urdf/mesh/rotor5_Link.STL</uri>
          </mesh>
        </geometry>
      </collision>
      <visual name='rotor5_Link_visual'>
        <pose>0 0 0 0 -0 0</pose>
        <geometry>
          <mesh>
            <scale>1 1 1</scale>
            <uri>model://uam_control_interface/urdf/mesh/rotor5_Link.STL</uri>
          </mesh>
        </geometry>
      </visual>
    </link>
    <joint name='rotor_5_joint' type='revolute'>
      <pose relative_to='base_link'>0.442074 -0.277802 0.033856 0 -0 0</pose>
      <parent>base_link</parent>
      <child>rotor6_Link</child>
      <axis>
        <xyz>-0.25 -0.433013 0.866025</xyz>
        <limit>
          <lower>0</lower>
          <upper>0</upper>
          <effort>0</effort>
          <velocity>0</velocity>
        </limit>
        <dynamics>
          <spring_reference>0</spring_reference>
          <spring_stiffness>0</spring_stiffness>
        </dynamics>
      </axis>
    </joint>
    <link name='rotor6_Link'>
      <pose relative_to='rotor_5_joint'>0 0 0 0 -0 0</pose>
      <inertial>
        <pose>-2.7e-05 -0.000763 -0.001153 0 -0 0</pose>
        <mass>0.0159143</mass>
        <inertia>
          <ixx>1.96957e-05</ixx>
          <ixy>5.28972e-05</ixy>
          <ixz>-3.11368e-05</ixz>
          <iyy>0.000204526</iyy>
          <iyz>7.94285e-06</iyz>
          <izz>0.000214159</izz>
        </inertia>
      </inertial>
      <collision name='rotor6_Link_collision'>
        <pose>0 0 0 0 -0 0</pose>
        <geometry>
          <mesh>
            <scale>1 1 1</scale>
            <uri>model://uam_control_interface/urdf/mesh/rotor6_Link.STL</uri>
          </mesh>
        </geometry>
      </collision>
      <visual name='rotor6_Link_visual'>
        <pose>0 0 0 0 -0 0</pose>
        <geometry>
          <mesh>
            <scale>1 1 1</scale>
            <uri>model://uam_control_interface/urdf/mesh/rotor6_Link.STL</uri>
          </mesh>
        </geometry>
      </visual>
    </link>
    <static>0</static>
    <plugin name='gazebo_ros_control' filename='libgazebo_ros_control.so'>
      <robotNamespace>/</robotNamespace>
    </plugin>
  </model>
</sdf>
